Workbook

Sheet Synthèse
A1: Synthèse – Investissement locatif à Paris : fonds propres vs dette
A2: Toutes les valeurs sont calculées à partir des feuilles Hypothèses et Projection.
A4: Indicateur | B4: 100% fonds propres | C4: Avec dette
A5: Opération
A6: Prix d'achat | B6: =Hypothèses!$B$8 -> 400000 | C6: =Hypothèses!$C$8 -> 400000
A7: Coût total (prix + notaire + travaux) | B7: =Hypothèses!$B$12 -> 440000 | C7: =Hypothèses!$C$12 -> 440000
A8: Emprunt | B8: =Hypothèses!$B$15 -> 0 | C8: =Hypothèses!$C$15 -> 352000
A9: Apport (fonds propres investis) | B9: =Hypothèses!$B$20 -> 440000 | C9: =Hypothèses!$C$20 -> 92224
A10: Mensualité crédit (hors assurance) | B10: =Hypothèses!$B$21 -> 0 | C10: =Hypothèses!$C$21 -> 1724.6647
A11: Rendements du bien (avant financement)
A12: Rendement brut (loyer annuel / prix) | B12: =Hypothèses!$B$24*12/Hypothèses!$B$8 -> 0.0384 | C12: =Hypothèses!$C$24*12/Hypothèses!$C$8 -> 0.0384
A13: Rendement net (NOI an 1 / coût total) | B13: ='Fonds propres'!C17/Hypothèses!$B$12 -> 0.022985018 | C13: ='Avec dette'!C17/Hypothèses!$C$12 -> 0.022985018
A14: Année 1
A15: Cash-flow après impôt (annuel) | B15: ='Fonds propres'!C32 -> 9823.8794 | C15: ='Avec dette'!C32 -> -11638.569
A16: Cash-flow après impôt (mensuel) = effort d'épargne si négatif | B16: ='Fonds propres'!C32/12 -> 818.65662 | C16: ='Avec dette'!C32/12 -> -969.88071
A17: Rendement sur fonds propres an 1 (cash-flow / apport) | B17: =IF(Hypothèses!$B$20>0,'Fonds propres'!C32/Hypothèses!$B$20,0) -> 0.022326999 | C17: =IF(Hypothèses!$C$20>0,'Avec dette'!C32/Hypothèses!$C$20,0) -> -0.12619891
A18: Sur la durée de détention
A19: Horizon (années) | B19: =Hypothèses!$B$43 -> 20 | C19: =Hypothèses!$C$43 -> 20
A20: Prix de revente | B20: =SUM('Fonds propres'!C34:AA34) -> 538742 | C20: =SUM('Avec dette'!C34:AA34) -> 538742
A21: Produit net de cession (après dette, frais, impôt PV) | B21: =SUM('Fonds propres'!C40:AA40) -> 477532.97 | C21: =SUM('Avec dette'!C40:AA40) -> 382259.82
A22: Somme des cash-flows après impôt | B22: =SUMPRODUCT('Fonds propres'!C4:AA4,'Fonds propres'!C32:AA32) -> 206206.62 | C22: =SUMPRODUCT('Avec dette'!C4:AA4,'Avec dette'!C32:AA32) -> -205405.78
A23: Gain net total pour l'investisseur | B23: =SUM('Fonds propres'!B42:AA42) -> 243739.59 | C23: =SUM('Avec dette'!B42:AA42) -> 84630.034
A24: Multiple du capital investi (x) | B24: =SUM('Fonds propres'!C42:AA42)/Hypothèses!$B$20 -> 1.5539536 | C24: =SUM('Avec dette'!C42:AA42)/Hypothèses!$C$20 -> 1.9176574
A25: TRI net annuel de l'investisseur | B25: =IRR('Fonds propres'!B42:AA42,0.05) -> 0.026631927 | C25: =IRR('Avec dette'!B42:AA42,0.05) -> 0.018726244
A27: Effet de levier (TRI avec dette – TRI fonds propres) | C27: =C25-B25 -> -0.007905683
A29: Lecture : la dette améliore le TRI uniquement si le rendement du bien (loyers + valorisation) dépasse le coût du crédit ; elle augmente aussi le risque (effort d'épargne mensuel).

Sheet Hypothèses
A1: Investissement locatif à Paris – Hypothèses
A2: Cellules en bleu = hypothèses modifiables (jaune = leviers clés). Colonne C reprend B par défaut (formule en noir) sauf pour le financement.
A4: Paramètre | B4: 1) 100% fonds propres | C4: 2) Avec dette | D4: Commentaire / source
A5: Le bien
A6: Surface (m²) | B6: 40 | C6: =B6 -> 40 | D6: Studio / 2 pièces type, hypothèse
A7: Prix d'achat (€/m²) | B7: 10000 | C7: =B7 -> 10000 | D7: Ordre de grandeur marché Paris ancien (~9 500–10 500 €/m²) – à ajuster
A8: Prix d'achat | B8: =B6*B7 -> 400000 | C8: =C6*C7 -> 400000
A9: Frais de notaire (% du prix) | B9: 0.075 | C9: =B9 -> 0.075 | D9: Ancien : ~7,5 % (droits + émoluments)
A10: Frais de notaire | B10: =B8*B9 -> 30000 | C10: =C8*C9 -> 30000
A11: Travaux + ameublement | B11: 10000 | C11: =B11 -> 10000 | D11: Mobilier et rafraîchissement pour location meublée (LMNP)
A12: Coût total de l'opération | B12: =B8+B10+B11 -> 440000 | C12: =C8+C10+C11 -> 440000
A13: Financement
A14: Part du coût total financée par emprunt | B14: 0 | C14: 0.8 | D14: Scénario 1 : 0 % / Scénario 2 : 80 % (apport ≥ 20 %)
A15: Montant emprunté | B15: =B12*B14 -> 0 | C15: =C12*C14 -> 352000
A16: Taux d'intérêt nominal | B16: 0.033 | C16: =B16 -> 0.033 | D16: Ordre de grandeur taux crédit immo 25 ans (≈3,0–3,6 %) – à ajuster
A17: Durée du prêt (années) | B17: 25 | C17: =B17 -> 25 | D17: Amortissable, taux fixe
A18: Assurance emprunteur (% capital initial / an) | B18: 0.003 | C18: =B18 -> 0.003 | D18: ≈0,30 % du capital initial
A19: Frais de dossier + garantie (% emprunt) | B19: 0.012 | C19: =B19 -> 0.012 | D19: Caution type Crédit Logement + dossier, ≈1,2 %
A20: Apport personnel (fonds propres investis) | B20: =B12-B15+B15*B19 -> 440000 | C20: =C12-C15+C15*C19 -> 92224 | D20: Coût total – emprunt + frais de garantie
A21: Mensualité hors assurance | B21: =IF(B15=0,0,-PMT(B16/12,B17*12,B15)) -> 0 | C21: =IF(C15=0,0,-PMT(C16/12,C17*12,C15)) -> 1724.6647
A22: Revenus locatifs (meublé)
A23: Loyer mensuel hors charges (€/m²) | B23: 32 | C23: =B23 -> 32 | D23: Meublé Paris petite surface ≈ 30–38 €/m² (respecter l'encadrement des loyers)
A24: Loyer mensuel | B24: =B6*B23 -> 1280 | C24: =C6*C23 -> 1280
A25: Vacance locative (% des loyers) | B25: 0.04 | C25: =B25 -> 0.04 | D25: ≈ 2 semaines / an
A26: Revalorisation annuelle des loyers | B26: 0.015 | C26: =B26 -> 0.015 | D26: Indexation type IRL, prudente
A27: Charges d'exploitation (année 1)
A28: Charges de copropriété non récupérables (€/an) | B28: 1200 | C28: =B28 -> 1200 | D28: ≈ 30 €/m²
A29: Taxe foncière (€/an) | B29: 1000 | C29: =B29 -> 1000 | D29: Paris, taux faible (≈ 25 €/m²)
A30: Assurance PNO (€/an) | B30: 200 | C30: =B30 -> 200
A31: Entretien / réparations (€/an) | B31: 500 | C31: =B31 -> 500
A32: Expert-comptable LMNP + CFE (€/an) | B32: 700 | C32: =B32 -> 700 | D32: Régime réel
A33: Gestion locative (% des loyers encaissés) | B33: 0.07 | C33: =B33 -> 0.07 | D33: Agence ≈ 6–8 % TTC (0 % si autogéré)
A34: Inflation des charges | B34: 0.02 | C34: =B34 -> 0.02
A35: Fiscalité (LMNP régime réel simplifié)
A36: Tranche marginale d'imposition (TMI) | B36: 0.3 | C36: =B36 -> 0.3 | D36: À adapter à l'investisseur
A37: Prélèvements sociaux | B37: 0.172 | C37: =B37 -> 0.172 | D37: 17,2 %
A38: Part amortissable du prix (hors terrain) | B38: 0.85 | C38: =B38 -> 0.85 | D38: Hypothèse usuelle 80–90 %
A39: Durée d'amortissement du bâti (ans) | B39: 40 | C39: =B39 -> 40
A40: Durée d'amortissement travaux/mobilier (ans) | B40: 10 | C40: =B40 -> 10
A41: Simplifications : déficits reportables sans limite, frais de notaire non amortis (prudent), pas de plafond de micro-BIC.
...

Sheet Fonds propres
A1: Projection – Fonds propres
A2: Montants en € ; flux de l'investisseur calculés jusqu'à l'année de revente (colonnes au-delà de l'horizon grisées).
A3: Année | B3: 0 | C3: 1 | D3: 2 | E3: 3 | F3: 4 | G3: 5 | H3: 6 | I3: 7 | J3: 8 | K3: 9 | L3: 10 | M3: 11 | N3: 12 | O3: 13 | P3: 14 | Q3: 15 | R3: 16 | S3: 17 | T3: 18 | U3: 19 | V3: 20 | W3: 21 | X3: 22 | Y3: 23 | Z3: 24 | AA3: 25
A4: Année détenue (1 = oui) | C4: =IF(C$3<=Hypothèses!$B$43,1,0) -> 1 | D4: =IF(D$3<=Hypothèses!$B$43,1,0) -> 1 | E4: =IF(E$3<=Hypothèses!$B$43,1,0) -> 1 | F4: =IF(F$3<=Hypothèses!$B$43,1,0) -> 1 | G4: =IF(G$3<=Hypothèses!$B$43,1,0) -> 1 | H4: =IF(H$3<=Hypothèses!$B$43,1,0) -> 1 | I4: =IF(I$3<=Hypothèses!$B$43,1,0) -> 1 | J4: =IF(J$3<=Hypothèses!$B$43,1,0) -> 1 | ... AA4: =IF(AA$3<=Hypothèses!$B$43,1,0) -> 0
A5: REVENUS LOCATIFS
A6: Loyer brut | C6: =Hypothèses!$B$24*12*(1+Hypothèses!$B$26)^(C$3-1) -> 15360 | D6: =Hypothèses!$B$24*12*(1+Hypothèses!$B$26)^(D$3-1) -> 15590.4 | E6: =Hypothèses!$B$24*12*(1+Hypothèses!$B$26)^(E$3-1) -> 15824.256 | F6: =Hypothèses!$B$24*12*(1+Hypothèses!$B$26)^(F$3-1) -> 16061.62 | G6: =Hypothèses!$B$24*12*(1+Hypothèses!$B$26)^(G$3-1) -> 16302.544 | H6: =Hypothèses!$B$24*12*(1+Hypothèses!$B$26)^(H$3-1) -> 16547.082 | I6: =Hypothèses!$B$24*12*(1+Hypothèses!$B$26)^(I$3-1) -> 16795.289 | J6: =Hypothèses!$B$24*12*(1+Hypothèses!$B$26)^(J$3-1) -> 17047.218 | ... AA6: =Hypothèses!$B$24*12*(1+Hypothèses!$B$26)^(AA$3-1) -> 21957.163
A7: Vacance locative | C7: =-C6*Hypothèses!$B$25 -> -614.4 | D7: =-D6*Hypothèses!$B$25 -> -623.616 | E7: =-E6*Hypothèses!$B$25 -> -632.97024 | F7: =-F6*Hypothèses!$B$25 -> -642.46479 | G7: =-G6*Hypothèses!$B$25 -> -652.10177 | H7: =-H6*Hypothèses!$B$25 -> -661.88329 | I7: =-I6*Hypothèses!$B$25 -> -671.81154 | J7: =-J6*Hypothèses!$B$25 -> -681.88871 | ... AA7: =-AA6*Hypothèses!$B$25 -> -878.28653
A8: Loyers encaissés | C8: =C6+C7 -> 14745.6 | D8: =D6+D7 -> 14966.784 | E8: =E6+E7 -> 15191.286 | F8: =F6+F7 -> 15419.155 | G8: =G6+G7 -> 15650.442 | H8: =H6+H7 -> 15885.199 | I8: =I6+I7 -> 16123.477 | J8: =J6+J7 -> 16365.329 | ... AA8: =AA6+AA7 -> 21078.877
A9: CHARGES D'EXPLOITATION
A10: Copropriété non récupérable | C10: =-Hypothèses!$B$28*(1+Hypothèses!$B$34)^(C$3-1) -> -1200 | D10: =-Hypothèses!$B$28*(1+Hypothèses!$B$34)^(D$3-1) -> -1224 | E10: =-Hypothèses!$B$28*(1+Hypothèses!$B$34)^(E$3-1) -> -1248.48 | F10: =-Hypothèses!$B$28*(1+Hypothèses!$B$34)^(F$3-1) -> -1273.4496 | G10: =-Hypothèses!$B$28*(1+Hypothèses!$B$34)^(G$3-1) -> -1298.9186 | H10: =-Hypothèses!$B$28*(1+Hypothèses!$B$34)^(H$3-1) -> -1324.897 | I10: =-Hypothèses!$B$28*(1+Hypothèses!$B$34)^(I$3-1) -> -1351.3949 | J10: =-Hypothèses!$B$28*(1+Hypothèses!$B$34)^(J$3-1) -> -1378.4228 | ... AA10: =-Hypothèses!$B$28*(1+Hypothèses!$B$34)^(AA$3-1) -> -1930.1247
A11: Taxe foncière | C11: =-Hypothèses!$B$29*(1+Hypothèses!$B$34)^(C$3-1) -> -1000 | D11: =-Hypothèses!$B$29*(1+Hypothèses!$B$34)^(D$3-1) -> -1020 | E11: =-Hypothèses!$B$29*(1+Hypothèses!$B$34)^(E$3-1) -> -1040.4 | F11: =-Hypothèses!$B$29*(1+Hypothèses!$B$34)^(F$3-1) -> -1061.208 | G11: =-Hypothèses!$B$29*(1+Hypothèses!$B$34)^(G$3-1) -> -1082.4322 | H11: =-Hypothèses!$B$29*(1+Hypothèses!$B$34)^(H$3-1) -> -1104.0808 | I11: =-Hypothèses!$B$29*(1+Hypothèses!$B$34)^(I$3-1) -> -1126.1624 | J11: =-Hypothèses!$B$29*(1+Hypothèses!$B$34)^(J$3-1) -> -1148.6857 | ... AA11: =-Hypothèses!$B$29*(1+Hypothèses!$B$34)^(AA$3-1) -> -1608.4372
A12: Assurance PNO | C12: =-Hypothèses!$B$30*(1+Hypothèses!$B$34)^(C$3-1) -> -200 | D12: =-Hypothèses!$B$30*(1+Hypothèses!$B$34)^(D$3-1) -> -204 | E12: =-Hypothèses!$B$30*(1+Hypothèses!$B$34)^(E$3-1) -> -208.08 | F12: =-Hypothèses!$B$30*(1+Hypothèses!$B$34)^(F$3-1) -> -212.2416 | G12: =-Hypothèses!$B$30*(1+Hypothèses!$B$34)^(G$3-1) -> -216.48643 | H12: =-Hypothèses!$B$30*(1+Hypothèses!$B$34)^(H$3-1) -> -220.81616 | I12: =-Hypothèses!$B$30*(1+Hypothèses!$B$34)^(I$3-1) -> -225.23248 | J12: =-Hypothèses!$B$30*(1+Hypothèses!$B$34)^(J$3-1) -> -229.73713 | ... AA12: =-Hypothèses!$B$30*(1+Hypothèses!$B$34)^(AA$3-1) -> -321.68745
A13: Entretien | C13: =-Hypothèses!$B$31*(1+Hypothèses!$B$34)^(C$3-1) -> -500 | D13: =-Hypothèses!$B$31*(1+Hypothèses!$B$34)^(D$3-1) -> -510 | E13: =-Hypothèses!$B$31*(1+Hypothèses!$B$34)^(E$3-1) -> -520.2 | F13: =-Hypothèses!$B$31*(1+Hypothèses!$B$34)^(F$3-1) -> -530.604 | G13: =-Hypothèses!$B$31*(1+Hypothèses!$B$34)^(G$3-1) -> -541.21608 | H13: =-Hypothèses!$B$31*(1+Hypothèses!$B$34)^(H$3-1) -> -552.0404 | I13: =-Hypothèses!$B$31*(1+Hypothèses!$B$34)^(I$3-1) -> -563.08121 | J13: =-Hypothèses!$B$31*(1+Hypothèses!$B$34)^(J$3-1) -> -574.34283 | ... AA13: =-Hypothèses!$B$31*(1+Hypothèses!$B$34)^(AA$3-1) -> -804.21862
A14: Comptabilité / CFE | C14: =-Hypothèses!$B$32*(1+Hypothèses!$B$34)^(C$3-1) -> -700 | D14: =-Hypothèses!$B$32*(1+Hypothèses!$B$34)^(D$3-1) -> -714 | E14: =-Hypothèses!$B$32*(1+Hypothèses!$B$34)^(E$3-1) -> -728.28 | F14: =-Hypothèses!$B$32*(1+Hypothèses!$B$34)^(F$3-1) -> -742.8456 | G14: =-Hypothèses!$B$32*(1+Hypothèses!$B$34)^(G$3-1) -> -757.70251 | H14: =-Hypothèses!$B$32*(1+Hypothèses!$B$34)^(H$3-1) -> -772.85656 | I14: =-Hypothèses!$B$32*(1+Hypothèses!$B$34)^(I$3-1) -> -788.31369 | J14: =-Hypothèses!$B$32*(1+Hypothèses!$B$34)^(J$3-1) -> -804.07997 | ... AA14: =-Hypothèses!$B$32*(1+Hypothèses!$B$34)^(AA$3-1) -> -1125.9061
A15: Gestion locative | C15: =-C8*Hypothèses!$B$33 -> -1032.192 | D15: =-D8*Hypothèses!$B$33 -> -1047.6749 | E15: =-E8*Hypothèses!$B$33 -> -1063.39 | F15: =-F8*Hypothèses!$B$33 -> -1079.3409 | G15: =-G8*Hypothèses!$B$33 -> -1095.531 | H15: =-H8*Hypothèses!$B$33 -> -1111.9639 | I15: =-I8*Hypothèses!$B$33 -> -1128.6434 | J15: =-J8*Hypothèses!$B$33 -> -1145.573 | ... AA15: =-AA8*Hypothèses!$B$33 -> -1475.5214
A16: Total charges | C16: =SUM(C10:C15) -> -4632.192 | D16: =SUM(D10:D15) -> -4719.6749 | E16: =SUM(E10:E15) -> -4808.83 | F16: =SUM(F10:F15) -> -4899.6897 | G16: =SUM(G10:G15) -> -4992.2867 | H16: =SUM(H10:H15) -> -5086.6548 | I16: =SUM(I10:I15) -> -5182.8281 | J16: =SUM(J10:J15) -> -5280.8414 | ... AA16: =SUM(AA10:AA15) -> -7265.8955
A17: Résultat d'exploitation (NOI) | C17: =C8+C16 -> 10113.408 | D17: =D8+D16 -> 10247.109 | E17: =E8+E16 -> 10382.456 | F17: =F8+F16 -> 10519.465 | G17: =G8+G16 -> 10658.156 | H17: =H8+H16 -> 10798.544 | I17: =I8+I16 -> 10940.649 | J17: =J8+J16 -> 11084.488 | ... AA17: =AA8+AA16 -> 13812.981
A18: FINANCEMENT
A19: Intérêts | C19: =IF(AND(Hypothèses!$B$15>0,C$3<=Hypothèses!$B$17),CUMIPMT(Hypothèses!$B$16/12,Hypothèses!$B$17*12,Hypothèses!$B$15,(C$3-1)*12+1,C$3*12,0),0) -> 0 | D19: =IF(AND(Hypothèses!$B$15>0,D$3<=Hypothèses!$B$17),CUMIPMT(Hypothèses!$B$16/12,Hypothèses!$B$17*12,Hypothèses!$B$15,(D$3-1)*12+1,D$3*12,0),0) -> 0 | E19: =IF(AND(Hypothèses!$B$15>0,E$3<=Hypothèses!$B$17),CUMIPMT(Hypothèses!$B$16/12,Hypothèses!$B$17*12,Hypothèses!$B$15,(E$3-1)*12+1,E$3*12,0),0) -> 0 | F19: =IF(AND(Hypothèses!$B$15>0,F$3<=Hypothèses!$B$17),CUMIPMT(Hypothèses!$B$16/12,Hypothèses!$B$17*12,Hypothèses!$B$15,(F$3-1)*12+1,F$3*12,0),0) -> 0 | G19: =IF(AND(Hypothèses!$B$15>0,G$3<=Hypothèses!$B$17),CUMIPMT(Hypothèses!$B$16/12,Hypothèses!$B$17*12,Hypothèses!$B$15,(G$3-1)*12+1,G$3*12,0),0) -> 0 | H19: =IF(AND(Hypothèses!$B$15>0,H$3<=Hypothèses!$B$17),CUMIPMT(Hypothèses!$B$16/12,Hypothèses!$B$17*12,Hypothèses!$B$15,(H$3-1)*12+1,H$3*12,0),0) -> 0 | I19: =IF(AND(Hypothèses!$B$15>0,I$3<=Hypothèses!$B$17),CUMIPMT(Hypothèses!$B$16/12,Hypothèses!$B$17*12,Hypothèses!$B$15,(I$3-1)*12+1,I$3*12,0),0) -> 0 | J19: =IF(AND(Hypothèses!$B$15>0,J$3<=Hypothèses!$B$17),CUMIPMT(Hypothèses!$B$16/12,Hypothèses!$B$17*12,Hypothèses!$B$15,(J$3-1)*12+1,J$3*12,0),0) -> 0 | ... AA19: =IF(AND(Hypothèses!$B$15>0,AA$3<=Hypothèses!$B$17),CUMIPMT(Hypothèses!$B$16/12,Hypothèses!$B$17*12,Hypothèses!$B$15,(AA$3-1)*12+1,AA$3*12,0),0) -> 0
A20: Assurance emprunt | C20: =IF(C$3<=Hypothèses!$B$17,-Hypothèses!$B$15*Hypothèses!$B$18,0) -> 0 | D20: =IF(D$3<=Hypothèses!$B$17,-Hypothèses!$B$15*Hypothèses!$B$18,0) -> 0 | E20: =IF(E$3<=Hypothèses!$B$17,-Hypothèses!$B$15*Hypothèses!$B$18,0) -> 0 | F20: =IF(F$3<=Hypothèses!$B$17,-Hypothèses!$B$15*Hypothèses!$B$18,0) -> 0 | G20: =IF(G$3<=Hypothèses!$B$17,-Hypothèses!$B$15*Hypothèses!$B$18,0) -> 0 | H20: =IF(H$3<=Hypothèses!$B$17,-Hypothèses!$B$15*Hypothèses!$B$18,0) -> 0 | I20: =IF(I$3<=Hypothèses!$B$17,-Hypothèses!$B$15*Hypothèses!$B$18,0) -> 0 | J20: =IF(J$3<=Hypothèses!$B$17,-Hypothèses!$B$15*Hypothèses!$B$18,0) -> 0 | ... AA20: =IF(AA$3<=Hypothèses!$B$17,-Hypothèses!$B$15*Hypothèses!$B$18,0) -> 0
A21: Remboursement du capital | C21: =IF(AND(Hypothèses!$B$15>0,C$3<=Hypothèses!$B$17),CUMPRINC(Hypothèses!$B$16/12,Hypothèses!$B$17*12,Hypothèses!$B$15,(C$3-1)*12+1,C$3*12,0),0) -> 0 | D21: =IF(AND(Hypothèses!$B$15>0,D$3<=Hypothèses!$B$17),CUMPRINC(Hypothèses!$B$16/12,Hypothèses!$B$17*12,Hypothèses!$B$15,(D$3-1)*12+1,D$3*12,0),0) -> 0 | E21: =IF(AND(Hypothèses!$B$15>0,E$3<=Hypothèses!$B$17),CUMPRINC(Hypothèses!$B$16/12,Hypothèses!$B$17*12,Hypothèses!$B$15,(E$3-1)*12+1,E$3*12,0),0) -> 0 | F21: =IF(AND(Hypothèses!$B$15>0,F$3<=Hypothèses!$B$17),CUMPRINC(Hypothèses!$B$16/12,Hypothèses!$B$17*12,Hypothèses!$B$15,(F$3-1)*12+1,F$3*12,0),0) -> 0 | G21: =IF(AND(Hypothèses!$B$15>0,G$3<=Hypothèses!$B$17),CUMPRINC(Hypothèses!$B$16/12,Hypothèses!$B$17*12,Hypothèses!$B$15,(G$3-1)*12+1,G$3*12,0),0) -> 0 | H21: =IF(AND(Hypothèses!$B$15>0,H$3<=Hypothèses!$B$17),CUMPRINC(Hypothèses!$B$16/12,Hypothèses!$B$17*12,Hypothèses!$B$15,(H$3-1)*12+1,H$3*12,0),0) -> 0 | I21: =IF(AND(Hypothèses!$B$15>0,I$3<=Hypothèses!$B$17),CUMPRINC(Hypothèses!$B$16/12,Hypothèses!$B$17*12,Hypothèses!$B$15,(I$3-1)*12+1,I$3*12,0),0) -> 0 | J21: =IF(AND(Hypothèses!$B$15>0,J$3<=Hypothèses!$B$17),CUMPRINC(Hypothèses!$B$16/12,Hypothèses!$B$17*12,Hypothèses!$B$15,(J$3-1)*12+1,J$3*12,0),0) -> 0 | ... AA21: =IF(AND(Hypothèses!$B$15>0,AA$3<=Hypothèses!$B$17),CUMPRINC(Hypothèses!$B$16/12,Hypothèses!$B$17*12,Hypothèses!$B$15,(AA$3-1)*12+1,AA$3*12,0),0) -> 0
A22: Capital restant dû (fin d'année) | B22: =Hypothèses!$B$15 -> 0 | C22: =IF(C$3<=Hypothèses!$B$17,MAX(0,Hypothèses!$B$15+SUM($C21:C21)),0) -> 0 | D22: =IF(D$3<=Hypothèses!$B$17,MAX(0,Hypothèses!$B$15+SUM($C21:D21)),0) -> 0 | E22: =IF(E$3<=Hypothèses!$B$17,MAX(0,Hypothèses!$B$15+SUM($C21:E21)),0) -> 0 | F22: =IF(F$3<=Hypothèses!$B$17,MAX(0,Hypothèses!$B$15+SUM($C21:F21)),0) -> 0 | G22: =IF(G$3<=Hypothèses!$B$17,MAX(0,Hypothèses!$B$15+SUM($C21:G21)),0) -> 0 | H22: =IF(H$3<=Hypothèses!$B$17,MAX(0,Hypothèses!$B$15+SUM($C21:H21)),0) -> 0 | I22: =IF(I$3<=Hypothèses!$B$17,MAX(0,Hypothèses!$B$15+SUM($C21:I21)),0) -> 0 | J22: =IF(J$3<=Hypothèses!$B$17,MAX(0,Hypothèses!$B$15+SUM($C21:J21)),0) -> 0 | ... AA22: =IF(AA$3<=Hypothèses!$B$17,MAX(0,Hypothèses!$B$15+SUM($C21:AA21)),0) -> 0
A23: FISCALITÉ LMNP RÉEL
A24: Amortissements déduits | C24: =IF(C$3<=Hypothèses!$B$39,Hypothèses!$B$8*Hypothèses!$B$38/Hypothèses!$B$39,0)+IF(C$3<=Hypothèses!$B$40,Hypothèses!$B$11/Hypothèses!$B$40,0) -> 9500 | D24: =IF(D$3<=Hypothèses!$B$39,Hypothèses!$B$8*Hypothèses!$B$38/Hypothèses!$B$39,0)+IF(D$3<=Hypothèses!$B$40,Hypothèses!$B$11/Hypothèses!$B$40,0) -> 9500 | E24: =IF(E$3<=Hypothèses!$B$39,Hypothèses!$B$8*Hypothèses!$B$38/Hypothèses!$B$39,0)+IF(E$3<=Hypothèses!$B$40,Hypothèses!$B$11/Hypothèses!$B$40,0) -> 9500 | F24: =IF(F$3<=Hypothèses!$B$39,Hypothèses!$B$8*Hypothèses!$B$38/Hypothèses!$B$39,0)+IF(F$3<=Hypothèses!$B$40,Hypothèses!$B$11/Hypothèses!$B$40,0) -> 9500 | G24: =IF(G$3<=Hypothèses!$B$39,Hypothèses!$B$8*Hypothèses!$B$38/Hypothèses!$B$39,0)+IF(G$3<=Hypothèses!$B$40,Hypothèses!$B$11/Hypothèses!$B$40,0) -> 9500 | H24: =IF(H$3<=Hypothèses!$B$39,Hypothèses!$B$8*Hypothèses!$B$38/Hypothèses!$B$39,0)+IF(H$3<=Hypothèses!$B$40,Hypothèses!$B$11/Hypothèses!$B$40,0) -> 9500 | I24: =IF(I$3<=Hypothèses!$B$39,Hypothèses!$B$8*Hypothèses!$B$38/Hypothèses!$B$39,0)+IF(I$3<=Hypothèses!$B$40,Hypothèses!$B$11/Hypothèses!$B$40,0) -> 9500 | J24: =IF(J$3<=Hypothèses!$B$39,Hypothèses!$B$8*Hypothèses!$B$38/Hypothèses!$B$39,0)+IF(J$3<=Hypothèses!$B$40,Hypothèses!$B$11/Hypothèses!$B$40,0) -> 9500 | ... AA24: =IF(AA$3<=Hypothèses!$B$39,Hypothèses!$B$8*Hypothèses!$B$38/Hypothèses!$B$39,0)+IF(AA$3<=Hypothèses!$B$40,Hypothèses!$B$11/Hypothèses!$B$40,0) -> 8500
A25: Résultat fiscal avant déficits | C25: =C17+C19+C20-C24 -> 613.408 | D25: =D17+D19+D20-D24 -> 747.10912 | E25: =E17+E19+E20-E24 -> 882.45576 | F25: =F17+F19+F20-F24 -> 1019.4654 | G25: =G17+G19+G20-G24 -> 1158.1556 | H25: =H17+H19+H20-H24 -> 1298.5442 | I25: =I17+I19+I20-I24 -> 1440.6489 | J25: =J17+J19+J20-J24 -> 1584.4877 | ... AA25: =AA17+AA19+AA20-AA24 -> 5312.9812
A26: Déficit reporté (début) | C26: 0 | D26: =C28 -> 0 | E26: =D28 -> 0 | F26: =E28 -> 0 | G26: =F28 -> 0 | H26: =G28 -> 0 | I26: =H28 -> 0 | J26: =I28 -> 0 | K26: =J28 -> 0 | ... AA26: =Z28 -> 0
A27: Base imposable | C27: =MAX(0,C25-C26) -> 613.408 | D27: =MAX(0,D25-D26) -> 747.10912 | E27: =MAX(0,E25-E26) -> 882.45576 | F27: =MAX(0,F25-F26) -> 1019.4654 | G27: =MAX(0,G25-G26) -> 1158.1556 | H27: =MAX(0,H25-H26) -> 1298.5442 | I27: =MAX(0,I25-I26) -> 1440.6489 | J27: =MAX(0,J25-J26) -> 1584.4877 | ... AA27: =MAX(0,AA25-AA26) -> 5312.9812
A28: Déficit reporté (fin) | C28: =MAX(0,C26-C25) -> 0 | D28: =MAX(0,D26-D25) -> 0 | E28: =MAX(0,E26-E25) -> 0 | F28: =MAX(0,F26-F25) -> 0 | G28: =MAX(0,G26-G25) -> 0 | H28: =MAX(0,H26-H25) -> 0 | I28: =MAX(0,I26-I25) -> 0 | J28: =MAX(0,J26-J25) -> 0 | ... AA28: =MAX(0,AA26-AA25) -> 0
A29: Impôt (IR + PS) | C29: =-C27*(Hypothèses!$B$36+Hypothèses!$B$37) -> -289.52858 | D29: =-D27*(Hypothèses!$B$36+Hypothèses!$B$37) -> -352.6355 | E29: =-E27*(Hypothèses!$B$36+Hypothèses!$B$37) -> -416.51912 | F29: =-F27*(Hypothèses!$B$36+Hypothèses!$B$37) -> -481.18767 | G29: =-G27*(Hypothèses!$B$36+Hypothèses!$B$37) -> -546.64946 | H29: =-H27*(Hypothèses!$B$36+Hypothèses!$B$37) -> -612.91286 | I29: =-I27*(Hypothèses!$B$36+Hypothèses!$B$37) -> -679.98628 | J29: =-J27*(Hypothèses!$B$36+Hypothèses!$B$37) -> -747.8782 | ... AA29: =-AA27*(Hypothèses!$B$36+Hypothèses!$B$37) -> -2507.7271
A30: CASH-FLOW
A31: Cash-flow avant impôt (après dette) | C31: =C17+C19+C20+C21 -> 10113.408 | D31: =D17+D19+D20+D21 -> 10247.109 | E31: =E17+E19+E20+E21 -> 10382.456 | F31: =F17+F19+F20+F21 -> 10519.465 | G31: =G17+G19+G20+G21 -> 10658.156 | H31: =H17+H19+H20+H21 -> 10798.544 | I31: =I17+I19+I20+I21 -> 10940.649 | J31: =J17+J19+J20+J21 -> 11084.488 | ... AA31: =AA17+AA19+AA20+AA21 -> 13812.981
A32: Cash-flow après impôt | C32: =C31+C29 -> 9823.8794 | D32: =D31+D29 -> 9894.4736 | E32: =E31+E29 -> 9965.9366 | F32: =F31+F29 -> 10038.278 | G32: =G31+G29 -> 10111.506 | H32: =H31+H29 -> 10185.631 | I32: =I31+I29 -> 10260.663 | J32: =J31+J29 -> 10336.61 | ... AA32: =AA31+AA29 -> 11305.254
A33: SORTIE (REVENTE)
A34: Prix de vente | C34: =IF(C$3=Hypothèses!$B$43,Hypothèses!$B$8*(1+Hypothèses!$B$44)^C$3,0) -> 0 | D34: =IF(D$3=Hypothèses!$B$43,Hypothèses!$B$8*(1+Hypothèses!$B$44)^D$3,0) -> 0 | E34: =IF(E$3=Hypothèses!$B$43,Hypothèses!$B$8*(1+Hypothèses!$B$44)^E$3,0) -> 0 | F34: =IF(F$3=Hypothèses!$B$43,Hypothèses!$B$8*(1+Hypothèses!$B$44)^F$3,0) -> 0 | G34: =IF(G$3=Hypothèses!$B$43,Hypothèses!$B$8*(1+Hypothèses!$B$44)^G$3,0) -> 0 | H34: =IF(H$3=Hypothèses!$B$43,Hypothèses!$B$8*(1+Hypothèses!$B$44)^H$3,0) -> 0 | I34: =IF(I$3=Hypothèses!$B$43,Hypothèses!$B$8*(1+Hypothèses!$B$44)^I$3,0) -> 0 | J34: =IF(J$3=Hypothèses!$B$43,Hypothèses!$B$8*(1+Hypothèses!$B$44)^J$3,0) -> 0 | ... AA34: =IF(AA$3=Hypothèses!$B$43,Hypothèses!$B$8*(1+Hypothèses!$B$44)^AA$3,0) -> 0
A35: Frais de vente | C35: =-C34*Hypothèses!$B$45 -> 0 | D35: =-D34*Hypothèses!$B$45 -> 0 | E35: =-E34*Hypothèses!$B$45 -> 0 | F35: =-F34*Hypothèses!$B$45 -> 0 | G35: =-G34*Hypothèses!$B$45 -> 0 | H35: =-H34*Hypothèses!$B$45 -> 0 | I35: =-I34*Hypothèses!$B$45 -> 0 | J35: =-J34*Hypothèses!$B$45 -> 0 | ... AA35: =-AA34*Hypothèses!$B$45 -> 0
A36: Remboursement du capital restant dû | C36: =IF(C$3=Hypothèses!$B$43,-C22,0) -> 0 | D36: =IF(D$3=Hypothèses!$B$43,-D22,0) -> 0 | E36: =IF(E$3=Hypothèses!$B$43,-E22,0) -> 0 | F36: =IF(F$3=Hypothèses!$B$43,-F22,0) -> 0 | G36: =IF(G$3=Hypothèses!$B$43,-G22,0) -> 0 | H36: =IF(H$3=Hypothèses!$B$43,-H22,0) -> 0 | I36: =IF(I$3=Hypothèses!$B$43,-I22,0) -> 0 | J36: =IF(J$3=Hypothèses!$B$43,-J22,0) -> 0 | ... AA36: =IF(AA$3=Hypothèses!$B$43,-AA22,0) -> 0
A37: Amortissements cumulés | C37: =C24 -> 9500 | D37: =C37+D24 -> 19000 | E37: =D37+E24 -> 28500 | F37: =E37+F24 -> 38000 | G37: =F37+G24 -> 47500 | H37: =G37+H24 -> 57000 | I37: =H37+I24 -> 66500 | J37: =I37+J24 -> 76000 | K37: =J37+K24 -> 85500 | ... AA37: =Z37+AA24 -> 222500
A38: Plus-value imposable | C38: =IF(C$3=Hypothèses!$B$43,MAX(0,C34+C35-Hypothèses!$B$8-Hypothèses!$B$10+Hypothèses!$B$49*C37),0) -> 0 | D38: =IF(D$3=Hypothèses!$B$43,MAX(0,D34+D35-Hypothèses!$B$8-Hypothèses!$B$10+Hypothèses!$B$49*D37),0) -> 0 | E38: =IF(E$3=Hypothèses!$B$43,MAX(0,E34+E35-Hypothèses!$B$8-Hypothèses!$B$10+Hypothèses!$B$49*E37),0) -> 0 | F38: =IF(F$3=Hypothèses!$B$43,MAX(0,F34+F35-Hypothèses!$B$8-Hypothèses!$B$10+Hypothèses!$B$49*F37),0) -> 0 | G38: =IF(G$3=Hypothèses!$B$43,MAX(0,G34+G35-Hypothèses!$B$8-Hypothèses!$B$10+Hypothèses!$B$49*G37),0) -> 0 | H38: =IF(H$3=Hypothèses!$B$43,MAX(0,H34+H35-Hypothèses!$B$8-Hypothèses!$B$10+Hypothèses!$B$49*H37),0) -> 0 | I38: =IF(I$3=Hypothèses!$B$43,MAX(0,I34+I35-Hypothèses!$B$8-Hypothèses!$B$10+Hypothèses!$B$49*I37),0) -> 0 | J38: =IF(J$3=Hypothèses!$B$43,MAX(0,J34+J35-Hypothèses!$B$8-Hypothèses!$B$10+Hypothèses!$B$49*J37),0) -> 0 | ... AA38: =IF(AA$3=Hypothèses!$B$43,MAX(0,AA34+AA35-Hypothèses!$B$8-Hypothèses!$B$10+Hypothèses!$B$49*AA37),0) -> 0
A39: Impôt sur plus-value | C39: =-(C38*(1-Hypothèses!$B$47)*Hypothèses!$B$46+C38*(1-Hypothèses!$B$48)*Hypothèses!$B$37) -> 0 | D39: =-(D38*(1-Hypothèses!$B$47)*Hypothèses!$B$46+D38*(1-Hypothèses!$B$48)*Hypothèses!$B$37) -> 0 | E39: =-(E38*(1-Hypothèses!$B$47)*Hypothèses!$B$46+E38*(1-Hypothèses!$B$48)*Hypothèses!$B$37) -> 0 | F39: =-(F38*(1-Hypothèses!$B$47)*Hypothèses!$B$46+F38*(1-Hypothèses!$B$48)*Hypothèses!$B$37) -> 0 | G39: =-(G38*(1-Hypothèses!$B$47)*Hypothèses!$B$46+G38*(1-Hypothèses!$B$48)*Hypothèses!$B$37) -> 0 | H39: =-(H38*(1-Hypothèses!$B$47)*Hypothèses!$B$46+H38*(1-Hypothèses!$B$48)*Hypothèses!$B$37) -> 0 | I39: =-(I38*(1-Hypothèses!$B$47)*Hypothèses!$B$46+I38*(1-Hypothèses!$B$48)*Hypothèses!$B$37) -> 0 | J39: =-(J38*(1-Hypothèses!$B$47)*Hypothèses!$B$46+J38*(1-Hypothèses!$B$48)*Hypothèses!$B$37) -> 0 | ... AA39: =-(AA38*(1-Hypothèses!$B$47)*Hypothèses!$B$46+AA38*(1-Hypothèses!$B$48)*Hypothèses!$B$37) -> 0
A40: Produit net de cession | C40: =C34+C35+C36+C39 -> 0 | D40: =D34+D35+D36+D39 -> 0 | E40: =E34+E35+E36+E39 -> 0 | F40: =F34+F35+F36+F39 -> 0 | G40: =G34+G35+G36+G39 -> 0 | H40: =H34+H35+H36+H39 -> 0 | I40: =I34+I35+I36+I39 -> 0 | J40: =J34+J35+J36+J39 -> 0 | ... AA40: =AA34+AA35+AA36+AA39 -> 0
...

Sheet Avec dette
A1: Projection – Avec dette
A2: Montants en € ; flux de l'investisseur calculés jusqu'à l'année de revente (colonnes au-delà de l'horizon grisées).
A3: Année | B3: 0 | C3: 1 | D3: 2 | E3: 3 | F3: 4 | G3: 5 | H3: 6 | I3: 7 | J3: 8 | K3: 9 | L3: 10 | M3: 11 | N3: 12 | O3: 13 | P3: 14 | Q3: 15 | R3: 16 | S3: 17 | T3: 18 | U3: 19 | V3: 20 | W3: 21 | X3: 22 | Y3: 23 | Z3: 24 | AA3: 25
A4: Année détenue (1 = oui) | C4: =IF(C$3<=Hypothèses!$C$43,1,0) -> 1 | D4: =IF(D$3<=Hypothèses!$C$43,1,0) -> 1 | E4: =IF(E$3<=Hypothèses!$C$43,1,0) -> 1 | F4: =IF(F$3<=Hypothèses!$C$43,1,0) -> 1 | G4: =IF(G$3<=Hypothèses!$C$43,1,0) -> 1 | H4: =IF(H$3<=Hypothèses!$C$43,1,0) -> 1 | I4: =IF(I$3<=Hypothèses!$C$43,1,0) -> 1 | J4: =IF(J$3<=Hypothèses!$C$43,1,0) -> 1 | ... AA4: =IF(AA$3<=Hypothèses!$C$43,1,0) -> 0
A5: REVENUS LOCATIFS
A6: Loyer brut | C6: =Hypothèses!$C$24*12*(1+Hypothèses!$C$26)^(C$3-1) -> 15360 | D6: =Hypothèses!$C$24*12*(1+Hypothèses!$C$26)^(D$3-1) -> 15590.4 | E6: =Hypothèses!$C$24*12*(1+Hypothèses!$C$26)^(E$3-1) -> 15824.256 | F6: =Hypothèses!$C$24*12*(1+Hypothèses!$C$26)^(F$3-1) -> 16061.62 | G6: =Hypothèses!$C$24*12*(1+Hypothèses!$C$26)^(G$3-1) -> 16302.544 | H6: =Hypothèses!$C$24*12*(1+Hypothèses!$C$26)^(H$3-1) -> 16547.082 | I6: =Hypothèses!$C$24*12*(1+Hypothèses!$C$26)^(I$3-1) -> 16795.289 | J6: =Hypothèses!$C$24*12*(1+Hypothèses!$C$26)^(J$3-1) -> 17047.218 | ... AA6: =Hypothèses!$C$24*12*(1+Hypothèses!$C$26)^(AA$3-1) -> 21957.163
A7: Vacance locative | C7: =-C6*Hypothèses!$C$25 -> -614.4 | D7: =-D6*Hypothèses!$C$25 -> -623.616 | E7: =-E6*Hypothèses!$C$25 -> -632.97024 | F7: =-F6*Hypothèses!$C$25 -> -642.46479 | G7: =-G6*Hypothèses!$C$25 -> -652.10177 | H7: =-H6*Hypothèses!$C$25 -> -661.88329 | I7: =-I6*Hypothèses!$C$25 -> -671.81154 | J7: =-J6*Hypothèses!$C$25 -> -681.88871 | ... AA7: =-AA6*Hypothèses!$C$25 -> -878.28653
A8: Loyers encaissés | C8: =C6+C7 -> 14745.6 | D8: =D6+D7 -> 14966.784 | E8: =E6+E7 -> 15191.286 | F8: =F6+F7 -> 15419.155 | G8: =G6+G7 -> 15650.442 | H8: =H6+H7 -> 15885.199 | I8: =I6+I7 -> 16123.477 | J8: =J6+J7 -> 16365.329 | ... AA8: =AA6+AA7 -> 21078.877
A9: CHARGES D'EXPLOITATION
A10: Copropriété non récupérable | C10: =-Hypothèses!$C$28*(1+Hypothèses!$C$34)^(C$3-1) -> -1200 | D10: =-Hypothèses!$C$28*(1+Hypothèses!$C$34)^(D$3-1) -> -1224 | E10: =-Hypothèses!$C$28*(1+Hypothèses!$C$34)^(E$3-1) -> -1248.48 | F10: =-Hypothèses!$C$28*(1+Hypothèses!$C$34)^(F$3-1) -> -1273.4496 | G10: =-Hypothèses!$C$28*(1+Hypothèses!$C$34)^(G$3-1) -> -1298.9186 | H10: =-Hypothèses!$C$28*(1+Hypothèses!$C$34)^(H$3-1) -> -1324.897 | I10: =-Hypothèses!$C$28*(1+Hypothèses!$C$34)^(I$3-1) -> -1351.3949 | J10: =-Hypothèses!$C$28*(1+Hypothèses!$C$34)^(J$3-1) -> -1378.4228 | ... AA10: =-Hypothèses!$C$28*(1+Hypothèses!$C$34)^(AA$3-1) -> -1930.1247
A11: Taxe foncière | C11: =-Hypothèses!$C$29*(1+Hypothèses!$C$34)^(C$3-1) -> -1000 | D11: =-Hypothèses!$C$29*(1+Hypothèses!$C$34)^(D$3-1) -> -1020 | E11: =-Hypothèses!$C$29*(1+Hypothèses!$C$34)^(E$3-1) -> -1040.4 | F11: =-Hypothèses!$C$29*(1+Hypothèses!$C$34)^(F$3-1) -> -1061.208 | G11: =-Hypothèses!$C$29*(1+Hypothèses!$C$34)^(G$3-1) -> -1082.4322 | H11: =-Hypothèses!$C$29*(1+Hypothèses!$C$34)^(H$3-1) -> -1104.0808 | I11: =-Hypothèses!$C$29*(1+Hypothèses!$C$34)^(I$3-1) -> -1126.1624 | J11: =-Hypothèses!$C$29*(1+Hypothèses!$C$34)^(J$3-1) -> -1148.6857 | ... AA11: =-Hypothèses!$C$29*(1+Hypothèses!$C$34)^(AA$3-1) -> -1608.4372
A12: Assurance PNO | C12: =-Hypothèses!$C$30*(1+Hypothèses!$C$34)^(C$3-1) -> -200 | D12: =-Hypothèses!$C$30*(1+Hypothèses!$C$34)^(D$3-1) -> -204 | E12: =-Hypothèses!$C$30*(1+Hypothèses!$C$34)^(E$3-1) -> -208.08 | F12: =-Hypothèses!$C$30*(1+Hypothèses!$C$34)^(F$3-1) -> -212.2416 | G12: =-Hypothèses!$C$30*(1+Hypothèses!$C$34)^(G$3-1) -> -216.48643 | H12: =-Hypothèses!$C$30*(1+Hypothèses!$C$34)^(H$3-1) -> -220.81616 | I12: =-Hypothèses!$C$30*(1+Hypothèses!$C$34)^(I$3-1) -> -225.23248 | J12: =-Hypothèses!$C$30*(1+Hypothèses!$C$34)^(J$3-1) -> -229.73713 | ... AA12: =-Hypothèses!$C$30*(1+Hypothèses!$C$34)^(AA$3-1) -> -321.68745
A13: Entretien | C13: =-Hypothèses!$C$31*(1+Hypothèses!$C$34)^(C$3-1) -> -500 | D13: =-Hypothèses!$C$31*(1+Hypothèses!$C$34)^(D$3-1) -> -510 | E13: =-Hypothèses!$C$31*(1+Hypothèses!$C$34)^(E$3-1) -> -520.2 | F13: =-Hypothèses!$C$31*(1+Hypothèses!$C$34)^(F$3-1) -> -530.604 | G13: =-Hypothèses!$C$31*(1+Hypothèses!$C$34)^(G$3-1) -> -541.21608 | H13: =-Hypothèses!$C$31*(1+Hypothèses!$C$34)^(H$3-1) -> -552.0404 | I13: =-Hypothèses!$C$31*(1+Hypothèses!$C$34)^(I$3-1) -> -563.08121 | J13: =-Hypothèses!$C$31*(1+Hypothèses!$C$34)^(J$3-1) -> -574.34283 | ... AA13: =-Hypothèses!$C$31*(1+Hypothèses!$C$34)^(AA$3-1) -> -804.21862
A14: Comptabilité / CFE | C14: =-Hypothèses!$C$32*(1+Hypothèses!$C$34)^(C$3-1) -> -700 | D14: =-Hypothèses!$C$32*(1+Hypothèses!$C$34)^(D$3-1) -> -714 | E14: =-Hypothèses!$C$32*(1+Hypothèses!$C$34)^(E$3-1) -> -728.28 | F14: =-Hypothèses!$C$32*(1+Hypothèses!$C$34)^(F$3-1) -> -742.8456 | G14: =-Hypothèses!$C$32*(1+Hypothèses!$C$34)^(G$3-1) -> -757.70251 | H14: =-Hypothèses!$C$32*(1+Hypothèses!$C$34)^(H$3-1) -> -772.85656 | I14: =-Hypothèses!$C$32*(1+Hypothèses!$C$34)^(I$3-1) -> -788.31369 | J14: =-Hypothèses!$C$32*(1+Hypothèses!$C$34)^(J$3-1) -> -804.07997 | ... AA14: =-Hypothèses!$C$32*(1+Hypothèses!$C$34)^(AA$3-1) -> -1125.9061
A15: Gestion locative | C15: =-C8*Hypothèses!$C$33 -> -1032.192 | D15: =-D8*Hypothèses!$C$33 -> -1047.6749 | E15: =-E8*Hypothèses!$C$33 -> -1063.39 | F15: =-F8*Hypothèses!$C$33 -> -1079.3409 | G15: =-G8*Hypothèses!$C$33 -> -1095.531 | H15: =-H8*Hypothèses!$C$33 -> -1111.9639 | I15: =-I8*Hypothèses!$C$33 -> -1128.6434 | J15: =-J8*Hypothèses!$C$33 -> -1145.573 | ... AA15: =-AA8*Hypothèses!$C$33 -> -1475.5214
A16: Total charges | C16: =SUM(C10:C15) -> -4632.192 | D16: =SUM(D10:D15) -> -4719.6749 | E16: =SUM(E10:E15) -> -4808.83 | F16: =SUM(F10:F15) -> -4899.6897 | G16: =SUM(G10:G15) -> -4992.2867 | H16: =SUM(H10:H15) -> -5086.6548 | I16: =SUM(I10:I15) -> -5182.8281 | J16: =SUM(J10:J15) -> -5280.8414 | ... AA16: =SUM(AA10:AA15) -> -7265.8955
A17: Résultat d'exploitation (NOI) | C17: =C8+C16 -> 10113.408 | D17: =D8+D16 -> 10247.109 | E17: =E8+E16 -> 10382.456 | F17: =F8+F16 -> 10519.465 | G17: =G8+G16 -> 10658.156 | H17: =H8+H16 -> 10798.544 | I17: =I8+I16 -> 10940.649 | J17: =J8+J16 -> 11084.488 | ... AA17: =AA8+AA16 -> 13812.981
A18: FINANCEMENT
A19: Intérêts | C19: =IF(AND(Hypothèses!$C$15>0,C$3<=Hypothèses!$C$17),CUMIPMT(Hypothèses!$C$16/12,Hypothèses!$C$17*12,Hypothèses!$C$15,(C$3-1)*12+1,C$3*12,0),0) -> -11477.399 | D19: =IF(AND(Hypothèses!$C$15>0,D$3<=Hypothèses!$C$17),CUMIPMT(Hypothèses!$C$16/12,Hypothèses!$C$17*12,Hypothèses!$C$15,(D$3-1)*12+1,D$3*12,0),0) -> -11168.542 | E19: =IF(AND(Hypothèses!$C$15>0,E$3<=Hypothèses!$C$17),CUMIPMT(Hypothèses!$C$16/12,Hypothèses!$C$17*12,Hypothèses!$C$15,(E$3-1)*12+1,E$3*12,0),0) -> -10849.337 | F19: =IF(AND(Hypothèses!$C$15>0,F$3<=Hypothèses!$C$17),CUMIPMT(Hypothèses!$C$16/12,Hypothèses!$C$17*12,Hypothèses!$C$15,(F$3-1)*12+1,F$3*12,0),0) -> -10519.438 | G19: =IF(AND(Hypothèses!$C$15>0,G$3<=Hypothèses!$C$17),CUMIPMT(Hypothèses!$C$16/12,Hypothèses!$C$17*12,Hypothèses!$C$15,(G$3-1)*12+1,G$3*12,0),0) -> -10178.486 | H19: =IF(AND(Hypothèses!$C$15>0,H$3<=Hypothèses!$C$17),CUMIPMT(Hypothèses!$C$16/12,Hypothèses!$C$17*12,Hypothèses!$C$15,(H$3-1)*12+1,H$3*12,0),0) -> -9826.111 | I19: =IF(AND(Hypothèses!$C$15>0,I$3<=Hypothèses!$C$17),CUMIPMT(Hypothèses!$C$16/12,Hypothèses!$C$17*12,Hypothèses!$C$15,(I$3-1)*12+1,I$3*12,0),0) -> -9461.93 | J19: =IF(AND(Hypothèses!$C$15>0,J$3<=Hypothèses!$C$17),CUMIPMT(Hypothèses!$C$16/12,Hypothèses!$C$17*12,Hypothèses!$C$15,(J$3-1)*12+1,J$3*12,0),0) -> -9085.5476 | ... AA19: =IF(AND(Hypothèses!$C$15>0,AA$3<=Hypothèses!$C$17),CUMIPMT(Hypothèses!$C$16/12,Hypothèses!$C$17*12,Hypothèses!$C$15,(AA$3-1)*12+1,AA$3*12,0),0) -> -365.24154
A20: Assurance emprunt | C20: =IF(C$3<=Hypothèses!$C$17,-Hypothèses!$C$15*Hypothèses!$C$18,0) -> -1056 | D20: =IF(D$3<=Hypothèses!$C$17,-Hypothèses!$C$15*Hypothèses!$C$18,0) -> -1056 | E20: =IF(E$3<=Hypothèses!$C$17,-Hypothèses!$C$15*Hypothèses!$C$18,0) -> -1056 | F20: =IF(F$3<=Hypothèses!$C$17,-Hypothèses!$C$15*Hypothèses!$C$18,0) -> -1056 | G20: =IF(G$3<=Hypothèses!$C$17,-Hypothèses!$C$15*Hypothèses!$C$18,0) -> -1056 | H20: =IF(H$3<=Hypothèses!$C$17,-Hypothèses!$C$15*Hypothèses!$C$18,0) -> -1056 | I20: =IF(I$3<=Hypothèses!$C$17,-Hypothèses!$C$15*Hypothèses!$C$18,0) -> -1056 | J20: =IF(J$3<=Hypothèses!$C$17,-Hypothèses!$C$15*Hypothèses!$C$18,0) -> -1056 | ... AA20: =IF(AA$3<=Hypothèses!$C$17,-Hypothèses!$C$15*Hypothèses!$C$18,0) -> -1056
A21: Remboursement du capital | C21: =IF(AND(Hypothèses!$C$15>0,C$3<=Hypothèses!$C$17),CUMPRINC(Hypothèses!$C$16/12,Hypothèses!$C$17*12,Hypothèses!$C$15,(C$3-1)*12+1,C$3*12,0),0) -> -9218.5779 | D21: =IF(AND(Hypothèses!$C$15>0,D$3<=Hypothèses!$C$17),CUMPRINC(Hypothèses!$C$16/12,Hypothèses!$C$17*12,Hypothèses!$C$15,(D$3-1)*12+1,D$3*12,0),0) -> -9527.4347 | E21: =IF(AND(Hypothèses!$C$15>0,E$3<=Hypothèses!$C$17),CUMPRINC(Hypothèses!$C$16/12,Hypothèses!$C$17*12,Hypothèses!$C$15,(E$3-1)*12+1,E$3*12,0),0) -> -9846.6393 | F21: =IF(AND(Hypothèses!$C$15>0,F$3<=Hypothèses!$C$17),CUMPRINC(Hypothèses!$C$16/12,Hypothèses!$C$17*12,Hypothèses!$C$15,(F$3-1)*12+1,F$3*12,0),0) -> -10176.538 | G21: =IF(AND(Hypothèses!$C$15>0,G$3<=Hypothèses!$C$17),CUMPRINC(Hypothèses!$C$16/12,Hypothèses!$C$17*12,Hypothèses!$C$15,(G$3-1)*12+1,G$3*12,0),0) -> -10517.49 | H21: =IF(AND(Hypothèses!$C$15>0,H$3<=Hypothèses!$C$17),CUMPRINC(Hypothèses!$C$16/12,Hypothèses!$C$17*12,Hypothèses!$C$15,(H$3-1)*12+1,H$3*12,0),0) -> -10869.866 | I21: =IF(AND(Hypothèses!$C$15>0,I$3<=Hypothèses!$C$17),CUMPRINC(Hypothèses!$C$16/12,Hypothèses!$C$17*12,Hypothèses!$C$15,(I$3-1)*12+1,I$3*12,0),0) -> -11234.047 | J21: =IF(AND(Hypothèses!$C$15>0,J$3<=Hypothèses!$C$17),CUMPRINC(Hypothèses!$C$16/12,Hypothèses!$C$17*12,Hypothèses!$C$15,(J$3-1)*12+1,J$3*12,0),0) -> -11610.429 | ... AA21: =IF(AND(Hypothèses!$C$15>0,AA$3<=Hypothèses!$C$17),CUMPRINC(Hypothèses!$C$16/12,Hypothèses!$C$17*12,Hypothèses!$C$15,(AA$3-1)*12+1,AA$3*12,0),0) -> -20330.735
A22: Capital restant dû (fin d'année) | B22: =Hypothèses!$C$15 -> 352000 | C22: =IF(C$3<=Hypothèses!$C$17,MAX(0,Hypothèses!$C$15+SUM($C21:C21)),0) -> 342781.42 | D22: =IF(D$3<=Hypothèses!$C$17,MAX(0,Hypothèses!$C$15+SUM($C21:D21)),0) -> 333253.99 | E22: =IF(E$3<=Hypothèses!$C$17,MAX(0,Hypothèses!$C$15+SUM($C21:E21)),0) -> 323407.35 | F22: =IF(F$3<=Hypothèses!$C$17,MAX(0,Hypothèses!$C$15+SUM($C21:F21)),0) -> 313230.81 | G22: =IF(G$3<=Hypothèses!$C$17,MAX(0,Hypothèses!$C$15+SUM($C21:G21)),0) -> 302713.32 | H22: =IF(H$3<=Hypothèses!$C$17,MAX(0,Hypothèses!$C$15+SUM($C21:H21)),0) -> 291843.45 | I22: =IF(I$3<=Hypothèses!$C$17,MAX(0,Hypothèses!$C$15+SUM($C21:I21)),0) -> 280609.41 | J22: =IF(J$3<=Hypothèses!$C$17,MAX(0,Hypothèses!$C$15+SUM($C21:J21)),0) -> 268998.98 | ... AA22: =IF(AA$3<=Hypothèses!$C$17,MAX(0,Hypothèses!$C$15+SUM($C21:AA21)),0) -> 0
A23: FISCALITÉ LMNP RÉEL
A24: Amortissements déduits | C24: =IF(C$3<=Hypothèses!$C$39,Hypothèses!$C$8*Hypothèses!$C$38/Hypothèses!$C$39,0)+IF(C$3<=Hypothèses!$C$40,Hypothèses!$C$11/Hypothèses!$C$40,0) -> 9500 | D24: =IF(D$3<=Hypothèses!$C$39,Hypothèses!$C$8*Hypothèses!$C$38/Hypothèses!$C$39,0)+IF(D$3<=Hypothèses!$C$40,Hypothèses!$C$11/Hypothèses!$C$40,0) -> 9500 | E24: =IF(E$3<=Hypothèses!$C$39,Hypothèses!$C$8*Hypothèses!$C$38/Hypothèses!$C$39,0)+IF(E$3<=Hypothèses!$C$40,Hypothèses!$C$11/Hypothèses!$C$40,0) -> 9500 | F24: =IF(F$3<=Hypothèses!$C$39,Hypothèses!$C$8*Hypothèses!$C$38/Hypothèses!$C$39,0)+IF(F$3<=Hypothèses!$C$40,Hypothèses!$C$11/Hypothèses!$C$40,0) -> 9500 | G24: =IF(G$3<=Hypothèses!$C$39,Hypothèses!$C$8*Hypothèses!$C$38/Hypothèses!$C$39,0)+IF(G$3<=Hypothèses!$C$40,Hypothèses!$C$11/Hypothèses!$C$40,0) -> 9500 | H24: =IF(H$3<=Hypothèses!$C$39,Hypothèses!$C$8*Hypothèses!$C$38/Hypothèses!$C$39,0)+IF(H$3<=Hypothèses!$C$40,Hypothèses!$C$11/Hypothèses!$C$40,0) -> 9500 | I24: =IF(I$3<=Hypothèses!$C$39,Hypothèses!$C$8*Hypothèses!$C$38/Hypothèses!$C$39,0)+IF(I$3<=Hypothèses!$C$40,Hypothèses!$C$11/Hypothèses!$C$40,0) -> 9500 | J24: =IF(J$3<=Hypothèses!$C$39,Hypothèses!$C$8*Hypothèses!$C$38/Hypothèses!$C$39,0)+IF(J$3<=Hypothèses!$C$40,Hypothèses!$C$11/Hypothèses!$C$40,0) -> 9500 | ... AA24: =IF(AA$3<=Hypothèses!$C$39,Hypothèses!$C$8*Hypothèses!$C$38/Hypothèses!$C$39,0)+IF(AA$3<=Hypothèses!$C$40,Hypothèses!$C$11/Hypothèses!$C$40,0) -> 8500
A25: Résultat fiscal avant déficits | C25: =C17+C19+C20-C24 -> -11919.991 | D25: =D17+D19+D20-D24 -> -11477.433 | E25: =E17+E19+E20-E24 -> -11022.882 | F25: =F17+F19+F20-F24 -> -10555.973 | G25: =G17+G19+G20-G24 -> -10076.331 | H25: =H17+H19+H20-H24 -> -9583.5669 | I25: =I17+I19+I20-I24 -> -9077.2811 | J25: =J17+J19+J20-J24 -> -8557.0599 | ... AA25: =AA17+AA19+AA20-AA24 -> 3891.7397
A26: Déficit reporté (début) | C26: 0 | D26: =C28 -> 11919.991 | E26: =D28 -> 23397.423 | F26: =E28 -> 34420.305 | G26: =F28 -> 44976.278 | H26: =G28 -> 55052.608 | I26: =H28 -> 64636.175 | J26: =I28 -> 73713.456 | K26: =J28 -> 82270.516 | ... AA26: =Z28 -> 121233.72
A27: Base imposable | C27: =MAX(0,C25-C26) -> 0 | D27: =MAX(0,D25-D26) -> 0 | E27: =MAX(0,E25-E26) -> 0 | F27: =MAX(0,F25-F26) -> 0 | G27: =MAX(0,G25-G26) -> 0 | H27: =MAX(0,H25-H26) -> 0 | I27: =MAX(0,I25-I26) -> 0 | J27: =MAX(0,J25-J26) -> 0 | ... AA27: =MAX(0,AA25-AA26) -> 0
A28: Déficit reporté (fin) | C28: =MAX(0,C26-C25) -> 11919.991 | D28: =MAX(0,D26-D25) -> 23397.423 | E28: =MAX(0,E26-E25) -> 34420.305 | F28: =MAX(0,F26-F25) -> 44976.278 | G28: =MAX(0,G26-G25) -> 55052.608 | H28: =MAX(0,H26-H25) -> 64636.175 | I28: =MAX(0,I26-I25) -> 73713.456 | J28: =MAX(0,J26-J25) -> 82270.516 | ... AA28: =MAX(0,AA26-AA25) -> 117341.98
A29: Impôt (IR + PS) | C29: =-C27*(Hypothèses!$C$36+Hypothèses!$C$37) -> 0 | D29: =-D27*(Hypothèses!$C$36+Hypothèses!$C$37) -> 0 | E29: =-E27*(Hypothèses!$C$36+Hypothèses!$C$37) -> 0 | F29: =-F27*(Hypothèses!$C$36+Hypothèses!$C$37) -> 0 | G29: =-G27*(Hypothèses!$C$36+Hypothèses!$C$37) -> 0 | H29: =-H27*(Hypothèses!$C$36+Hypothèses!$C$37) -> 0 | I29: =-I27*(Hypothèses!$C$36+Hypothèses!$C$37) -> 0 | J29: =-J27*(Hypothèses!$C$36+Hypothèses!$C$37) -> 0 | ... AA29: =-AA27*(Hypothèses!$C$36+Hypothèses!$C$37) -> 0
A30: CASH-FLOW
A31: Cash-flow avant impôt (après dette) | C31: =C17+C19+C20+C21 -> -11638.569 | D31: =D17+D19+D20+D21 -> -11504.867 | E31: =E17+E19+E20+E21 -> -11369.521 | F31: =F17+F19+F20+F21 -> -11232.511 | G31: =G17+G19+G20+G21 -> -11093.821 | H31: =H17+H19+H20+H21 -> -10953.432 | I31: =I17+I19+I20+I21 -> -10811.328 | J31: =J17+J19+J20+J21 -> -10667.489 | ... AA31: =AA17+AA19+AA20+AA21 -> -7938.9954
A32: Cash-flow après impôt | C32: =C31+C29 -> -11638.569 | D32: =D31+D29 -> -11504.867 | E32: =E31+E29 -> -11369.521 | F32: =F31+F29 -> -11232.511 | G32: =G31+G29 -> -11093.821 | H32: =H31+H29 -> -10953.432 | I32: =I31+I29 -> -10811.328 | J32: =J31+J29 -> -10667.489 | ... AA32: =AA31+AA29 -> -7938.9954
A33: SORTIE (REVENTE)
A34: Prix de vente | C34: =IF(C$3=Hypothèses!$C$43,Hypothèses!$C$8*(1+Hypothèses!$C$44)^C$3,0) -> 0 | D34: =IF(D$3=Hypothèses!$C$43,Hypothèses!$C$8*(1+Hypothèses!$C$44)^D$3,0) -> 0 | E34: =IF(E$3=Hypothèses!$C$43,Hypothèses!$C$8*(1+Hypothèses!$C$44)^E$3,0) -> 0 | F34: =IF(F$3=Hypothèses!$C$43,Hypothèses!$C$8*(1+Hypothèses!$C$44)^F$3,0) -> 0 | G34: =IF(G$3=Hypothèses!$C$43,Hypothèses!$C$8*(1+Hypothèses!$C$44)^G$3,0) -> 0 | H34: =IF(H$3=Hypothèses!$C$43,Hypothèses!$C$8*(1+Hypothèses!$C$44)^H$3,0) -> 0 | I34: =IF(I$3=Hypothèses!$C$43,Hypothèses!$C$8*(1+Hypothèses!$C$44)^I$3,0) -> 0 | J34: =IF(J$3=Hypothèses!$C$43,Hypothèses!$C$8*(1+Hypothèses!$C$44)^J$3,0) -> 0 | ... AA34: =IF(AA$3=Hypothèses!$C$43,Hypothèses!$C$8*(1+Hypothèses!$C$44)^AA$3,0) -> 0
A35: Frais de vente | C35: =-C34*Hypothèses!$C$45 -> 0 | D35: =-D34*Hypothèses!$C$45 -> 0 | E35: =-E34*Hypothèses!$C$45 -> 0 | F35: =-F34*Hypothèses!$C$45 -> 0 | G35: =-G34*Hypothèses!$C$45 -> 0 | H35: =-H34*Hypothèses!$C$45 -> 0 | I35: =-I34*Hypothèses!$C$45 -> 0 | J35: =-J34*Hypothèses!$C$45 -> 0 | ... AA35: =-AA34*Hypothèses!$C$45 -> 0
A36: Remboursement du capital restant dû | C36: =IF(C$3=Hypothèses!$C$43,-C22,0) -> 0 | D36: =IF(D$3=Hypothèses!$C$43,-D22,0) -> 0 | E36: =IF(E$3=Hypothèses!$C$43,-E22,0) -> 0 | F36: =IF(F$3=Hypothèses!$C$43,-F22,0) -> 0 | G36: =IF(G$3=Hypothèses!$C$43,-G22,0) -> 0 | H36: =IF(H$3=Hypothèses!$C$43,-H22,0) -> 0 | I36: =IF(I$3=Hypothèses!$C$43,-I22,0) -> 0 | J36: =IF(J$3=Hypothèses!$C$43,-J22,0) -> 0 | ... AA36: =IF(AA$3=Hypothèses!$C$43,-AA22,0) -> 0
A37: Amortissements cumulés | C37: =C24 -> 9500 | D37: =C37+D24 -> 19000 | E37: =D37+E24 -> 28500 | F37: =E37+F24 -> 38000 | G37: =F37+G24 -> 47500 | H37: =G37+H24 -> 57000 | I37: =H37+I24 -> 66500 | J37: =I37+J24 -> 76000 | K37: =J37+K24 -> 85500 | ... AA37: =Z37+AA24 -> 222500
A38: Plus-value imposable | C38: =IF(C$3=Hypothèses!$C$43,MAX(0,C34+C35-Hypothèses!$C$8-Hypothèses!$C$10+Hypothèses!$C$49*C37),0) -> 0 | D38: =IF(D$3=Hypothèses!$C$43,MAX(0,D34+D35-Hypothèses!$C$8-Hypothèses!$C$10+Hypothèses!$C$49*D37),0) -> 0 | E38: =IF(E$3=Hypothèses!$C$43,MAX(0,E34+E35-Hypothèses!$C$8-Hypothèses!$C$10+Hypothèses!$C$49*E37),0) -> 0 | F38: =IF(F$3=Hypothèses!$C$43,MAX(0,F34+F35-Hypothèses!$C$8-Hypothèses!$C$10+Hypothèses!$C$49*F37),0) -> 0 | G38: =IF(G$3=Hypothèses!$C$43,MAX(0,G34+G35-Hypothèses!$C$8-Hypothèses!$C$10+Hypothèses!$C$49*G37),0) -> 0 | H38: =IF(H$3=Hypothèses!$C$43,MAX(0,H34+H35-Hypothèses!$C$8-Hypothèses!$C$10+Hypothèses!$C$49*H37),0) -> 0 | I38: =IF(I$3=Hypothèses!$C$43,MAX(0,I34+I35-Hypothèses!$C$8-Hypothèses!$C$10+Hypothèses!$C$49*I37),0) -> 0 | J38: =IF(J$3=Hypothèses!$C$43,MAX(0,J34+J35-Hypothèses!$C$8-Hypothèses!$C$10+Hypothèses!$C$49*J37),0) -> 0 | ... AA38: =IF(AA$3=Hypothèses!$C$43,MAX(0,AA34+AA35-Hypothèses!$C$8-Hypothèses!$C$10+Hypothèses!$C$49*AA37),0) -> 0
A39: Impôt sur plus-value | C39: =-(C38*(1-Hypothèses!$C$47)*Hypothèses!$C$46+C38*(1-Hypothèses!$C$48)*Hypothèses!$C$37) -> 0 | D39: =-(D38*(1-Hypothèses!$C$47)*Hypothèses!$C$46+D38*(1-Hypothèses!$C$48)*Hypothèses!$C$37) -> 0 | E39: =-(E38*(1-Hypothèses!$C$47)*Hypothèses!$C$46+E38*(1-Hypothèses!$C$48)*Hypothèses!$C$37) -> 0 | F39: =-(F38*(1-Hypothèses!$C$47)*Hypothèses!$C$46+F38*(1-Hypothèses!$C$48)*Hypothèses!$C$37) -> 0 | G39: =-(G38*(1-Hypothèses!$C$47)*Hypothèses!$C$46+G38*(1-Hypothèses!$C$48)*Hypothèses!$C$37) -> 0 | H39: =-(H38*(1-Hypothèses!$C$47)*Hypothèses!$C$46+H38*(1-Hypothèses!$C$48)*Hypothèses!$C$37) -> 0 | I39: =-(I38*(1-Hypothèses!$C$47)*Hypothèses!$C$46+I38*(1-Hypothèses!$C$48)*Hypothèses!$C$37) -> 0 | J39: =-(J38*(1-Hypothèses!$C$47)*Hypothèses!$C$46+J38*(1-Hypothèses!$C$48)*Hypothèses!$C$37) -> 0 | ... AA39: =-(AA38*(1-Hypothèses!$C$47)*Hypothèses!$C$46+AA38*(1-Hypothèses!$C$48)*Hypothèses!$C$37) -> 0
A40: Produit net de cession | C40: =C34+C35+C36+C39 -> 0 | D40: =D34+D35+D36+D39 -> 0 | E40: =E34+E35+E36+E39 -> 0 | F40: =F34+F35+F36+F39 -> 0 | G40: =G34+G35+G36+G39 -> 0 | H40: =H34+H35+H36+H39 -> 0 | I40: =I34+I35+I36+I39 -> 0 | J40: =J34+J35+J36+J39 -> 0 | ... AA40: =AA34+AA35+AA36+AA39 -> 0
...
